<?xml version="1.0"?>

<robot name="ThreeLinkAssn2">
  <link name="base_link">

  </link>

  <link name="base_platform">
    <inertial>
      <origin xyz="0 0 0.55" rpy="0 0 0" />
      <mass value="1" />
      <inertia ixx="1" ixy="0" ixz="0" iyy="0.083" iyz="0" izz="1" />
    </inertial>
    <visual>
      <origin xyz="0 0 .55" rpy="0 0 0" />
      <geometry>
         <cylinder length="1.1" radius="0.075" />
      </geometry>
      <material name="purple">
	       <color rgba="1 0 1 1" />
      </material>
    </visual>
    <collision>
      <origin xyz="0 0 .55" rpy="0 0 0" />
      <geometry>
        <cylinder length="1.1" radius="0.075" />
      </geometry>
    </collision>
  </link>

  <link name="dummy1">
    <inertial>
      <origin xyz="0 0.0 0.1" rpy="0 0 0" />
      <mass value="0.5" />
      <inertia ixx="1" ixy="0" ixz="0" iyy="0.083" iyz="0" izz="1" />
    </inertial>
  </link>

  <joint name="trunk_dummy" type="continuous">
    <parent link="base_link" />
    <child link="dummy1" />
    <origin xyz="0 0 0" rpy = "0 0 0"/>
    <axis xyz="0 0 1" />
    <dynamics damping="0.1" />
  </joint>

  <joint name="trunk" type="continuous">
    <parent link="base_link" />
    <child link="base_platform" />
    <origin xyz="0 0 0" />
    <axis xyz="0 0 1" />
    <dynamics damping="0.01" />
  </joint>


  <link name="lower_link">
    <inertial>
      <origin xyz="0 -0.1 0.5" rpy="0 0 0" />
      <mass value="1" />
      <inertia ixx="1" ixy="0" ixz="0" iyy="0.083" iyz="0" izz="1" />
    </inertial>
    <visual>
      <origin xyz="0 -0.1 0.5" rpy="0 0 0" />
      <geometry>
         <cylinder length="1.1" radius=".05" />
      </geometry>
      <material name="red">
	       <color rgba="1 0 0 1" />
      </material>
    </visual>
    <collision>
      <origin xyz="0 -0.1 0.5" rpy="0 0 0" />
      <geometry>
        <cylinder length="1.1" radius="0.05" />
      </geometry>
    </collision>
  </link>

  <link name="dummy2">
    <inertial>
      <origin xyz="0 0.1 0.0" rpy="0 0 0" />
      <mass value="0.5" />
      <inertia ixx="1" ixy="0" ixz="0" iyy="1" iyz="0" izz="0.083" />
    </inertial>
  </link>

  <joint name="shoulder_dummy" type="continuous">
    <parent link="base_platform" />
    <child link="dummy2" />
    <origin xyz="0 0.05 1" rpy="0.0 0 0 "/>
    <axis xyz="0 1 0" />
    <dynamics damping="0.1" />
  </joint>


  <joint name="shoulder" type="continuous">
    <parent link="base_platform" />
    <child link="lower_link" />
    <origin xyz="0 0 1" />
    <axis xyz="0 1 0" />
    <dynamics damping="0.01" />
  </joint>

  <link name="upper_link">
    <inertial>
      <origin xyz="0 0 0.5" rpy="0 0 0" />
      <mass value="1" />
      <inertia ixx="1" ixy="0" ixz="0" iyy="0.33" iyz="0" izz="1" />
    </inertial>
    <visual>
      <origin xyz="0 0 0.5" rpy="0 0 0" />
      <geometry>
         <cylinder length="1.1" radius=".05" />
      </geometry>
      <material name="blue">
        <color rgba="0 0 1 1" />
      </material>
    </visual>
    <collision>
      <origin xyz="0 0 0.5" rpy="0 0 0" />
      <geometry>
        <cylinder length="1.1" radius="0.05" />
      </geometry>
    </collision>
  </link>

  <link name="dummy3">
    <inertial>
      <origin xyz="0 0.1 0.0" rpy="0 0 0" />
      <mass value="0.5" />
      <inertia ixx="1" ixy="0" ixz="0" iyy="1" iyz="0" izz="0.083" />
    </inertial>
  </link>

  <joint name="elbow_dummy" type="continuous">
    <parent link="lower_link" />
    <child link="dummy3" />
    <origin xyz="0.0 0.0 1.0" rpy="0.0 0 0 "/>
    <axis xyz="0 1 0" />
    <dynamics damping="0.1" />
  </joint>

  <joint name="elbow" type="continuous">
    <parent link="lower_link" />
    <child link="upper_link" />
    <origin xyz="0 -0.05 1.0" />
    <axis xyz="0 1 0" />
    <dynamics damping="0.01" />
  </joint>


</robot>
